Workbook

Sheet Jan - Formula
A1: {=[1]Jan!$A$1:$P$3103} -> job_title_short | B1: job_title | C1: job_location | D1: job_via | E1: job_schedule_type | F1: job_work_from_home | G1: search_location | H1: job_posted_date | I1: job_no_degree_mention | J1: job_health_insurance | K1: job_country | L1: salary_rate | M1: salary_year_avg | N1: salary_hour_avg | O1: company_name | P1: job_skills
A2: Data Scientist | B2: Data Scientist - TikTok Ads | C2: Mountain View, CA | D2: via LinkedIn | E2: Full-time | F2: FALSE | G2: California, United States | H2: 44928.626 | I2: FALSE | J2: TRUE | K2: United States | L2: year | M2: 224500 | N2: 0 | O2: TikTok | P2: ['r', 'python', 'matlab', 'sql']
A3: Data Scientist | B3: Data Scientist - Technical Platform | C3: Mountain View, CA | D3: via LinkedIn | E3: Full-time | F3: FALSE | G3: California, United States | H3: 44938.17 | I3: FALSE | J3: TRUE | K3: United States | L3: year | M3: 157500 | N3: 0 | O3: TikTok | P3: ['sql', 'python']
A4: Data Scientist | B4: Data Scientist - Computer Vision | C4: Paris, France | D4: via Ai-Jobs.net | E4: Full-time | F4: FALSE | G4: France | H4: 44956.343 | I4: FALSE | J4: FALSE | K4: France | L4: year | M4: 88128 | N4: 0 | O4: digiRocks | P4: ['python', 'c++', 'pytorch', 'tensorflow', 'keras']
A5: Data Scientist | B5: Senior Actuarial Consultant and Data Scientist - Remote | C5: Las Vegas, NV | D5: via Las Vegas, NV - Geebo | E5: Full-time | F5: FALSE | G5: California, United States | H5: 44953.004 | I5: FALSE | J5: TRUE | K5: United States | L5: hour | M5: 0 | N5: 24 | O5: UnitedHealth Group | P5: ['r', 'python', 'vba', 'sas', 'sas', 'sql', 'databricks', 'excel']
A6: Data Scientist | B6: Data Scientist Digital Effectiveness Operations & Technology Analytics | C6: Sun City, AZ | D6: via ZipRecruiter | E6: Full-time | F6: FALSE | G6: California, United States | H6: 44955.42 | I6: FALSE | J6: TRUE | K6: United States | L6: year | M6: 105800 | N6: 0 | O6: Cox Communications | P6: ['sql', 'python', 'aws', 'pandas', 'numpy', 'scikit-learn', 'pyspark', 'tableau']
A7: Data Scientist | B7: Data Scientist - Marketing Analytics | C7: Irving, TX | D7: via LinkedIn | E7: Full-time | F7: FALSE | G7: Texas, United States | H7: 44950.668 | I7: FALSE | J7: TRUE | K7: United States | L7: year | M7: 115000 | N7: 0 | O7: Cottonwood Financial | P7: ['sql', 'sas', 'sas', 'python', 'r']
A8: Senior Data Analyst | B8: Senior Data Analyst Business Optimization Intelligence | C8: Bailey's Crossroads, VA | D8: via ZipRecruiter | E8: Full-time | F8: FALSE | G8: New York, United States | H8: 44930.417 | I8: FALSE | J8: TRUE | K8: United States | L8: year | M8: 96500 | N8: 0 | O8: Cox Communications | P8: ['sql', 'snowflake', 'aws', 'microstrategy', 'tableau', 'excel']
A9: Data Engineer | B9: IT & Strategy Talent Programme - AI/ML and Data Engineer | C9: Hamburg, Germany | D9: via Ai-Jobs.net | E9: Full-time | F9: FALSE | G9: Germany | H9: 44938.864 | I9: FALSE | J9: FALSE | K9: Germany | L9: year | M9: 98301.5 | N9: 0 | O9: Vattenfall | P9: ['azure']
A10: Senior Data Scientist | B10: Senior Data Scientist | C10: El Mirage, AZ | D10: via ZipRecruiter | E10: Full-time | F10: FALSE | G10: California, United States | H10: 44955.42 | I10: FALSE | J10: TRUE | K10: United States | L10: year | M10: 116700 | N10: 0 | O10: Cox Communications | P10: ['sql', 'r', 'python', 'scala', 'java', 'c++', 'sas', 'sas', 'aws', 'spark', 'ggplot2', 'pandas', 'numpy', 'scikit-learn', 'tableau']
A11: Data Engineer | B11: Data Engineer | C11: Chicago, IL | D11: via Indeed | E11: Full-time | F11: FALSE | G11: California, United States | H11: 44939.798 | I11: FALSE | J11: TRUE | K11: United States | L11: year | M11: 102500 | N11: 0 | O11: Alliant Credit Union | P11: ['sql', 'azure', 'tableau']
A12: Senior Data Scientist | B12: Senior Data Scientist | C12: Austin, TX | D12: via Indeed | E12: Full-time | F12: FALSE | G12: Texas, United States | H12: 44930.92 | I12: FALSE | J12: TRUE | K12: United States | L12: year | M12: 145000 | N12: 0 | O12: CyberCoders | P12: ['python', 'azure', 'pytorch', 'tensorflow', 'opencv', 'datarobot']
A13: Data Engineer | B13: Systems & Data Engineer | C13: Boston, MA | D13: via LinkedIn | E13: Full-time | F13: FALSE | G13: Illinois, United States | H13: 44952.675 | I13: FALSE | J13: TRUE | K13: United States | L13: year | M13: 75000 | N13: 0 | O13: New England Board of Higher Education | P13: ['sql', 'python', 'r', 'java', 'scala', 'aws', 'azure', 'tableau']
... A17: Data Scientist | B17: Data Scientist I | C17: Boston, MA | D17: via ZipRecruiter | E17: Full-time | F17: FALSE | G17: New York, United States | H17: 44931.669 | I17: FALSE | J17: FALSE | K17: United States | L17: year | M17: 57500 | N17: 0 | O17: Tresume and Asta CRS | P17: ['r', 'sql', 'python', 'scala', 'java', 'c++']
A18: Data Analyst | B18: Lead-Data Analyst | C18: St James, MO | D18: via My ArkLaMiss Jobs | E18: Full-time | F18: FALSE | G18: Illinois, United States | H18: 44928.751 | I18: FALSE | J18: TRUE | K18: United States | L18: year | M18: 144481.5 | N18: 0 | O18: EDWARD JONES | P18: 0
A19: Data Scientist | B19: Data Science Instructor | C19: San Antonio, TX | D19: via LinkedIn | E19: Full-time | F19: FALSE | G19: Sudan | H19: 44936.752 | I19: FALSE | J19: TRUE | K19: Sudan | L19: year | M19: 77500 | N19: 0 | O19: Codeup | P19: ['python', 'sql', 'matplotlib', 'seaborn', 'spark', 'hadoop', 'jupyter', 'tableau']
A20: Data Engineer | B20: Big Data Engineer | C20: Chicago, IL | D20: via LinkedIn | E20: Full-time | F20: FALSE | G20: Sudan | H20: 44952.328 | I20: FALSE | J20: FALSE | K20: Sudan | L20: year | M20: 105000 | N20: 0 | O20: Robert Half | P20: ['python', 'sql', 'go', 'aws', 'databricks', 'spark', 'pyspark', 'airflow', 'alteryx', 'tableau']
A21: Data Analyst | B21: Institutional Credit Management - Lending Data Analyst - Vice... | C21: Pinellas Park, FL | D21: via ComputerWork | E21: Full-time | F21: FALSE | G21: Florida, United States | H21: 44951.669 | I21: FALSE | J21: FALSE | K21: United States | L21: year | M21: 132315 | N21: 0 | O21: Citi | P21: ['cognos', 'tableau']
A22: Senior Data Scientist | B22: AI/ML - Senior Data Science Manager, AI/ML Data | C22: Cupertino, CA | D22: via My Champlain Valley Jobs | E22: Full-time | F22: FALSE | G22: California, United States | H22: 44938.754 | I22: FALSE | J22: TRUE | K22: United States | L22: year | M22: 173000 | N22: 0 | O22: Apple | P22: 0
A23: Data Analyst | B23: Experian Data Analyst Remote / Telecommute Jobs | C23: Anywhere | D23: via Clearance Jobs | E23: Full-time | F23: TRUE | G23: New York, United States | H23: 44929.894 | I23: FALSE | J23: FALSE | K23: United States | L23: year | M23: 112500 | N23: 0 | O23: Seneca Resources, LLC | P23: ['aws', 'linux']
A24: Data Scientist | B24: Electronics Data Scientist Intern | C24: Anywhere | D24: via Indeed | E24: Full-time | F24: TRUE | G24: California, United States | H24: 44953.379 | I24: FALSE | J24: FALSE | K24: United States | L24: hour | M24: 0 | N24: 21.75 | O24: MilliporeSigma | P24: ['excel', 'outlook']
A25: Data Scientist | B25: Data Scientist (Genomics/Genetics, Python, AWS) - no c2c | C25: Anywhere | D25: via LinkedIn | E25: Contractor | F25: TRUE | G25: Texas, United States | H25: 44935.753 | I25: FALSE | J25: FALSE | K25: United States | L25: hour | M25: 0 | N25: 66.5 | O25: neteffects | P25: ['python', 'r', 'sql', 'java', 'aws', 'gcp', 'airflow', 'docker', 'git', 'kubernetes']
A26: Senior Data Analyst | B26: Senior Data Analyst | C26: Ontario, CA | D26: via Indeed | E26: Full-time | F26: FALSE | G26: California, United States | H26: 44937.418 | I26: FALSE | J26: TRUE | K26: United States | L26: hour | M26: 0 | N26: 34.875 | O26: Prime Healthcare Management Inc | P26: ['sql', 'excel']
A27: Data Analyst | B27: Data Analyst (Remote) | C27: Anywhere | D27: via Indeed | E27: Full-time | F27: TRUE | G27: Georgia | H27: 44940.405 | I27: FALSE | J27: FALSE | K27: United States | L27: year | M27: 52500 | N27: 0 | O27: Acosta, Inc. | P27: ['windows', 'excel', 'word', 'powerpoint', 'power bi']
A28: Data Engineer | B28: Sr. Data Engineer | C28: Austin, TX | D28: via Indeed | E28: Full-time | F28: FALSE | G28: Georgia | H28: 44947.598 | I28: TRUE | J28: FALSE | K28: United States | L28: year | M28: 164500 | N28: 0 | O28: Charles Schwab | P28: ['sql', 'python', 'java', 'gcp', 'bigquery', 'aws', 'vmware', 'pandas', 'spark', 'airflow', 'kafka', 'splunk', 'tableau', 'jira', 'confluence']
A29: Data Engineer | B29: Scientific Data Engineer (Remote Friendly) | C29: Anywhere | D29: via LinkedIn | E29: Full-time | F29: TRUE | G29: Texas, United States | H29: 44951.975 | I29: FALSE | J29: FALSE | K29: United States | L29: year | M29: 149874 | N29: 0 | O29: Berkeley Lab | P29: ['python', 'java', 'javascript', 'bash', 'nosql', 'mysql', 'oracle', 'aws', 'linux']
A30: Data Analyst | B30: Lead Business Data Analyst - Global Delivery Services | C30: Santa Fe, NM | D30: via DirectlyApply | E30: Full-time | F30: FALSE | G30: Sudan | H30: 44932.163 | I30: TRUE | J30: FALSE | K30: Sudan | L30: year | M30: 115775 | N30: 0 | O30: UKG (Ultimate Kronos Group) | P30: ['power bi', 'excel', 'tableau']
A31: Senior Data Analyst | B31: Senior Data Analyst - Cox Communities | C31: Oakton, VA | D31: via ZipRecruiter | E31: Full-time | F31: FALSE | G31: New York, United States | H31: 44930.417 | I31: FALSE | J31: TRUE | K31: United States | L31: year | M31: 96500 | N31: 0 | O31: Cox Communications | P31: ['sql', 'alteryx', 'tableau']
A32: Senior Data Scientist | B32: Senior Data Scientist , Health Equity – Chicago, Boston, OR Remote | C32: Anywhere | D32: via Indeed | E32: Full-time | F32: TRUE | G32: Illinois, United States | H32: 44942.905 | I32: FALSE | J32: TRUE | K32: United States | L32: year | M32: 135000 | N32: 0 | O32: CVS Health | P32: ['python', 'sql', 'gcp', 'azure', 'aws', 'hadoop']
A33: Data Scientist | B33: Manufacturing Data Scientist | C33: Englewood, CO | D33: via Indeed | E33: Full-time | F33: FALSE | G33: Sudan | H33: 44939.891 | I33: FALSE | J33: FALSE | K33: Sudan | L33: year | M33: 110000 | N33: 0 | O33: Scytec Consulting Inc. | P33: ['sql', 'nosql', 'mongodb', 'mongodb', 'c#', 'sql server', 'azure', 'aws', 'git']
A34: Data Engineer | B34: Data Engineer | C34: New York, NY | D34: via LinkedIn | E34: Full-time | F34: FALSE | G34: Texas, United States | H34: 44950.632 | I34: FALSE | J34: FALSE | K34: United States | L34: year | M34: 155000 | N34: 0 | O34: Revel IT | P34: ['sql', 'nosql', 'python', 'ruby', 'ruby', 'mysql', 'redshift', 'aws', 'tableau']
A35: Data Scientist | B35: Mathematics Statistician or Statistician (Data Scientist) 12 Month... | C35: Buffalo, NY | D35: via Buffalo, NY - Geebo | E35: Full-time | F35: FALSE | G35: Illinois, United States | H35: 44942.003 | I35: FALSE | J35: TRUE | K35: United States | L35: hour | M35: 0 | N35: 24 | O35: Internal Revenue Service | P35: ['c', 'r', 'python', 'sql', 'java', 'oracle']
A36: Data Analyst | B36: Data Analyst | C36: 0 | D36: via LinkedIn | E36: Full-time | F36: FALSE | G36: New York, United States | H36: 44929.686 | I36: TRUE | J36: FALSE | K36: United States | L36: year | M36: 97500 | N36: 0 | O36: Robert Half | P36: ['sql', 't-sql', 'sql server', 'azure', 'ssrs', 'ssis']
A37: Data Engineer | B37: Data Engineer | C37: Washington, DC | D37: via PHL17 Jobs | E37: Full-time | F37: FALSE | G37: Georgia | H37: 44941.583 | I37: FALSE | J37: FALSE | K37: United States | L37: year | M37: 145000 | N37: 0 | O37: Peraton | P37: ['python', 'sql', 'neo4j', 'mysql', 'aws', 'spark', 'express', 'splunk', 'git', 'jira', 'confluence']
A38: Data Engineer | B38: Data Engineer - A4370 | C38: Pleasanton, CA | D38: via Ai-Jobs.net | E38: Full-time | F38: FALSE | G38: California, United States | H38: 44937.839 | I38: FALSE | J38: TRUE | K38: United States | L38: year | M38: 147500 | N38: 0 | O38: Nisum | P38: ['sql', 'spark']
A39: Senior Data Engineer | B39: Senior Data Engineer | C39: Woonsocket, RI | D39: via Indeed | E39: Full-time | F39: FALSE | G39: Illinois, United States | H39: 44933.921 | I39: FALSE | J39: TRUE | K39: United States | L39: year | M39: 135000 | N39: 0 | O39: CVS Health | P39: ['sql', 'python', 'bash', 'oracle', 'snowflake', 'azure', 'gcp', 'hadoop']
A40: Senior Data Analyst | B40: Senior Data Analyst, Business Optimization | C40: Smyrna, GA | D40: via ZipRecruiter | E40: Full-time | F40: FALSE | G40: Georgia | H40: 44953.436 | I40: FALSE | J40: TRUE | K40: United States | L40: year | M40: 96500 | N40: 0 | O40: Cox Communications | P40: ['swift', 'sql', 'excel', 'powerpoint', 'microstrategy', 'tableau']
A41: Data Engineer | B41: Data Engineer | C41: Malvern, PA | D41: via Dice | E41: Full-time | F41: FALSE | G41: Georgia | H41: 44935.863 | I41: TRUE | J41: FALSE | K41: United States | L41: year | M41: 70000 | N41: 0 | O41: Acadia Technologies, Inc. | P41: ['pyspark']
A42: Senior Data Scientist | B42: Senior Data Scientist - ProServe | C42: Lakeland, FL | D42: via Lakeland, FL - Geebo | E42: Full-time | F42: FALSE | G42: Florida, United States | H42: 44929.983 | I42: FALSE | J42: FALSE | K42: United States | L42: hour | M42: 0 | N42: 24 | O42: Amazon Web Services, Inc. | P42: ['aws', 'mxnet', 'tensorflow', 'pytorch', 'scikit-learn']
A43: Senior Data Analyst | B43: Senior Data Analyst | C43: New York, NY | D43: via LinkedIn | E43: Full-time | F43: FALSE | G43: New York, United States | H43: 44930.061 | I43: FALSE | J43: TRUE | K43: United States | L43: year | M43: 170000 | N43: 0 | O43: Harnham | P43: ['sql', 'python', 'r', 'tableau', 'power bi', 'looker']
...

Sheet Jan - Copy & Paste
A1: job_title_short | B1: job_title | C1: job_location | D1: job_via | E1: job_schedule_type | F1: job_work_from_home | G1: search_location | H1: job_posted_date | I1: job_no_degree_mention | J1: job_health_insurance | K1: job_country | L1: salary_rate | M1: salary_year_avg | N1: salary_hour_avg | O1: company_name | P1: job_skills
A2: Data Scientist | B2: Data Scientist - TikTok Ads | C2: Mountain View, CA | D2: via LinkedIn | E2: Full-time | F2: FALSE | G2: California, United States | H2: 44928.626 | I2: FALSE | J2: TRUE | K2: United States | L2: year | M2: 224500 | O2: TikTok | P2: ['r', 'python', 'matlab', 'sql']
A3: Data Scientist | B3: Data Scientist - Technical Platform | C3: Mountain View, CA | D3: via LinkedIn | E3: Full-time | F3: FALSE | G3: California, United States | H3: 44938.17 | I3: FALSE | J3: TRUE | K3: United States | L3: year | M3: 157500 | O3: TikTok | P3: ['sql', 'python']
A4: Data Scientist | B4: Data Scientist - Computer Vision | C4: Paris, France | D4: via Ai-Jobs.net | E4: Full-time | F4: FALSE | G4: France | H4: 44956.343 | I4: FALSE | J4: FALSE | K4: France | L4: year | M4: 88128 | O4: digiRocks | P4: ['python', 'c++', 'pytorch', 'tensorflow', 'keras']
A5: Data Scientist | B5: Senior Actuarial Consultant and Data Scientist - Remote | C5: Las Vegas, NV | D5: via Las Vegas, NV - Geebo | E5: Full-time | F5: FALSE | G5: California, United States | H5: 44953.004 | I5: FALSE | J5: TRUE | K5: United States | L5: hour | N5: 24 | O5: UnitedHealth Group | P5: ['r', 'python', 'vba', 'sas', 'sas', 'sql', 'databricks', 'excel']
A6: Data Scientist | B6: Data Scientist Digital Effectiveness Operations & Technology Analytics | C6: Sun City, AZ | D6: via ZipRecruiter | E6: Full-time | F6: FALSE | G6: California, United States | H6: 44955.42 | I6: FALSE | J6: TRUE | K6: United States | L6: year | M6: 105800 | O6: Cox Communications | P6: ['sql', 'python', 'aws', 'pandas', 'numpy', 'scikit-learn', 'pyspark', 'tableau']
A7: Data Scientist | B7: Data Scientist - Marketing Analytics | C7: Irving, TX | D7: via LinkedIn | E7: Full-time | F7: FALSE | G7: Texas, United States | H7: 44950.668 | I7: FALSE | J7: TRUE | K7: United States | L7: year | M7: 115000 | O7: Cottonwood Financial | P7: ['sql', 'sas', 'sas', 'python', 'r']
A8: Senior Data Analyst | B8: Senior Data Analyst Business Optimization Intelligence | C8: Bailey's Crossroads, VA | D8: via ZipRecruiter | E8: Full-time | F8: FALSE | G8: New York, United States | H8: 44930.417 | I8: FALSE | J8: TRUE | K8: United States | L8: year | M8: 96500 | O8: Cox Communications | P8: ['sql', 'snowflake', 'aws', 'microstrategy', 'tableau', 'excel']
A9: Data Engineer | B9: IT & Strategy Talent Programme - AI/ML and Data Engineer | C9: Hamburg, Germany | D9: via Ai-Jobs.net | E9: Full-time | F9: FALSE | G9: Germany | H9: 44938.864 | I9: FALSE | J9: FALSE | K9: Germany | L9: year | M9: 98301.5 | O9: Vattenfall | P9: ['azure']
A10: Senior Data Scientist | B10: Senior Data Scientist | C10: El Mirage, AZ | D10: via ZipRecruiter | E10: Full-time | F10: FALSE | G10: California, United States | H10: 44955.42 | I10: FALSE | J10: TRUE | K10: United States | L10: year | M10: 116700 | O10: Cox Communications | P10: ['sql', 'r', 'python', 'scala', 'java', 'c++', 'sas', 'sas', 'aws', 'spark', 'ggplot2', 'pandas', 'numpy', 'scikit-learn', 'tableau']
A11: Data Engineer | B11: Data Engineer | C11: Chicago, IL | D11: via Indeed | E11: Full-time | F11: FALSE | G11: California, United States | H11: 44939.798 | I11: FALSE | J11: TRUE | K11: United States | L11: year | M11: 102500 | O11: Alliant Credit Union | P11: ['sql', 'azure', 'tableau']
A12: Senior Data Scientist | B12: Senior Data Scientist | C12: Austin, TX | D12: via Indeed | E12: Full-time | F12: FALSE | G12: Texas, United States | H12: 44930.92 | I12: FALSE | J12: TRUE | K12: United States | L12: year | M12: 145000 | O12: CyberCoders | P12: ['python', 'azure', 'pytorch', 'tensorflow', 'opencv', 'datarobot']
A13: Data Engineer | B13: Systems & Data Engineer | C13: Boston, MA | D13: via LinkedIn | E13: Full-time | F13: FALSE | G13: Illinois, United States | H13: 44952.675 | I13: FALSE | J13: TRUE | K13: United States | L13: year | M13: 75000 | O13: New England Board of Higher Education | P13: ['sql', 'python', 'r', 'java', 'scala', 'aws', 'azure', 'tableau']
A14: Data Engineer | B14: Data Engineer | C14: Anywhere | D14: via LinkedIn | E14: Full-time | F14: TRUE | G14: Florida, United States | H14: 44944.634 | I14: TRUE | J14: FALSE | K14: United States | L14: year | M14: 105000 | O14: HirePlace | P14: ['no-sql', 'sql', 'python', 'scala', 'java', 'bash', 'powershell', 'azure', 'databricks', 'spark']
A15: Data Engineer | B15: Jr. Data Engineer | C15: Madison, WI | D15: via Ladders | E15: Full-time | F15: FALSE | G15: New York, United States | H15: 44935.087 | I15: FALSE | J15: FALSE | K15: United States | L15: year | M15: 90000 | O15: Baker Tilly | P15: ['sql', 'python', 'r', 'sql server', 'azure', 'databricks']
A16: Data Scientist | B16: Data Science Manager, Specialist Master - SFL Scientific | C16: San Jose, CA | D16: via Ladders | E16: Full-time | F16: FALSE | G16: California, United States | H16: 44946.515 | I16: FALSE | J16: FALSE | K16: United States | L16: year | M16: 200000 | O16: Deloitte | P16: ['python', 'aws', 'azure', 'gcp', 'keras', 'tensorflow', 'pytorch', 'pandas', 'scikit-learn', 'jupyter']
A17: Data Scientist | B17: Data Scientist I | C17: Boston, MA | D17: via ZipRecruiter | E17: Full-time | F17: FALSE | G17: New York, United States | H17: 44931.669 | I17: FALSE | J17: FALSE | K17: United States | L17: year | M17: 57500 | O17: Tresume and Asta CRS | P17: ['r', 'sql', 'python', 'scala', 'java', 'c++']
A18: Data Analyst | B18: Lead-Data Analyst | C18: St James, MO | D18: via My ArkLaMiss Jobs | E18: Full-time | F18: FALSE | G18: Illinois, United States | H18: 44928.751 | I18: FALSE | J18: TRUE | K18: United States | L18: year | M18: 144481.5 | O18: EDWARD JONES
A19: Data Scientist | B19: Data Science Instructor | C19: San Antonio, TX | D19: via LinkedIn | E19: Full-time | F19: FALSE | G19: Sudan | H19: 44936.752 | I19: FALSE | J19: TRUE | K19: Sudan | L19: year | M19: 77500 | O19: Codeup | P19: ['python', 'sql', 'matplotlib', 'seaborn', 'spark', 'hadoop', 'jupyter', 'tableau']
A20: Data Engineer | B20: Big Data Engineer | C20: Chicago, IL | D20: via LinkedIn | E20: Full-time | F20: FALSE | G20: Sudan | H20: 44952.328 | I20: FALSE | J20: FALSE | K20: Sudan | L20: year | M20: 105000 | O20: Robert Half | P20: ['python', 'sql', 'go', 'aws', 'databricks', 'spark', 'pyspark', 'airflow', 'alteryx', 'tableau']
A21: Data Analyst | B21: Institutional Credit Management - Lending Data Analyst - Vice... | C21: Pinellas Park, FL | D21: via ComputerWork | E21: Full-time | F21: FALSE | G21: Florida, United States | H21: 44951.669 | I21: FALSE | J21: FALSE | K21: United States | L21: year | M21: 132315 | O21: Citi | P21: ['cognos', 'tableau']
A22: Senior Data Scientist | B22: AI/ML - Senior Data Science Manager, AI/ML Data | C22: Cupertino, CA | D22: via My Champlain Valley Jobs | E22: Full-time | F22: FALSE | G22: California, United States | H22: 44938.754 | I22: FALSE | J22: TRUE | K22: United States | L22: year | M22: 173000 | O22: Apple
A23: Data Analyst | B23: Experian Data Analyst Remote / Telecommute Jobs | C23: Anywhere | D23: via Clearance Jobs | E23: Full-time | F23: TRUE | G23: New York, United States | H23: 44929.894 | I23: FALSE | J23: FALSE | K23: United States | L23: year | M23: 112500 | O23: Seneca Resources, LLC | P23: ['aws', 'linux']
A24: Data Scientist | B24: Electronics Data Scientist Intern | C24: Anywhere | D24: via Indeed | E24: Full-time | F24: TRUE | G24: California, United States | H24: 44953.379 | I24: FALSE | J24: FALSE | K24: United States | L24: hour | N24: 21.75 | O24: MilliporeSigma | P24: ['excel', 'outlook']
A25: Data Scientist | B25: Data Scientist (Genomics/Genetics, Python, AWS) - no c2c | C25: Anywhere | D25: via LinkedIn | E25: Contractor | F25: TRUE | G25: Texas, United States | H25: 44935.753 | I25: FALSE | J25: FALSE | K25: United States | L25: hour | N25: 66.5 | O25: neteffects | P25: ['python', 'r', 'sql', 'java', 'aws', 'gcp', 'airflow', 'docker', 'git', 'kubernetes']
A26: Senior Data Analyst | B26: Senior Data Analyst | C26: Ontario, CA | D26: via Indeed | E26: Full-time | F26: FALSE | G26: California, United States | H26: 44937.418 | I26: FALSE | J26: TRUE | K26: United States | L26: hour | N26: 34.875 | O26: Prime Healthcare Management Inc | P26: ['sql', 'excel']
A27: Data Analyst | B27: Data Analyst (Remote) | C27: Anywhere | D27: via Indeed | E27: Full-time | F27: TRUE | G27: Georgia | H27: 44940.405 | I27: FALSE | J27: FALSE | K27: United States | L27: year | M27: 52500 | O27: Acosta, Inc. | P27: ['windows', 'excel', 'word', 'powerpoint', 'power bi']
A28: Data Engineer | B28: Sr. Data Engineer | C28: Austin, TX | D28: via Indeed | E28: Full-time | F28: FALSE | G28: Georgia | H28: 44947.598 | I28: TRUE | J28: FALSE | K28: United States | L28: year | M28: 164500 | O28: Charles Schwab | P28: ['sql', 'python', 'java', 'gcp', 'bigquery', 'aws', 'vmware', 'pandas', 'spark', 'airflow', 'kafka', 'splunk', 'tableau', 'jira', 'confluence']
A29: Data Engineer | B29: Scientific Data Engineer (Remote Friendly) | C29: Anywhere | D29: via LinkedIn | E29: Full-time | F29: TRUE | G29: Texas, United States | H29: 44951.975 | I29: FALSE | J29: FALSE | K29: United States | L29: year | M29: 149874 | O29: Berkeley Lab | P29: ['python', 'java', 'javascript', 'bash', 'nosql', 'mysql', 'oracle', 'aws', 'linux']
A30: Data Analyst | B30: Lead Business Data Analyst - Global Delivery Services | C30: Santa Fe, NM | D30: via DirectlyApply | E30: Full-time | F30: FALSE | G30: Sudan | H30: 44932.163 | I30: TRUE | J30: FALSE | K30: Sudan | L30: year | M30: 115775 | O30: UKG (Ultimate Kronos Group) | P30: ['power bi', 'excel', 'tableau']
A31: Senior Data Analyst | B31: Senior Data Analyst - Cox Communities | C31: Oakton, VA | D31: via ZipRecruiter | E31: Full-time | F31: FALSE | G31: New York, United States | H31: 44930.417 | I31: FALSE | J31: TRUE | K31: United States | L31: year | M31: 96500 | O31: Cox Communications | P31: ['sql', 'alteryx', 'tableau']
A32: Senior Data Scientist | B32: Senior Data Scientist , Health Equity – Chicago, Boston, OR Remote | C32: Anywhere | D32: via Indeed | E32: Full-time | F32: TRUE | G32: Illinois, United States | H32: 44942.905 | I32: FALSE | J32: TRUE | K32: United States | L32: year | M32: 135000 | O32: CVS Health | P32: ['python', 'sql', 'gcp', 'azure', 'aws', 'hadoop']
A33: Data Scientist | B33: Manufacturing Data Scientist | C33: Englewood, CO | D33: via Indeed | E33: Full-time | F33: FALSE | G33: Sudan | H33: 44939.891 | I33: FALSE | J33: FALSE | K33: Sudan | L33: year | M33: 110000 | O33: Scytec Consulting Inc. | P33: ['sql', 'nosql', 'mongodb', 'mongodb', 'c#', 'sql server', 'azure', 'aws', 'git']
A34: Data Engineer | B34: Data Engineer | C34: New York, NY | D34: via LinkedIn | E34: Full-time | F34: FALSE | G34: Texas, United States | H34: 44950.632 | I34: FALSE | J34: FALSE | K34: United States | L34: year | M34: 155000 | O34: Revel IT | P34: ['sql', 'nosql', 'python', 'ruby', 'ruby', 'mysql', 'redshift', 'aws', 'tableau']
A35: Data Scientist | B35: Mathematics Statistician or Statistician (Data Scientist) 12 Month... | C35: Buffalo, NY | D35: via Buffalo, NY - Geebo | E35: Full-time | F35: FALSE | G35: Illinois, United States | H35: 44942.003 | I35: FALSE | J35: TRUE | K35: United States | L35: hour | N35: 24 | O35: Internal Revenue Service | P35: ['c', 'r', 'python', 'sql', 'java', 'oracle']
A36: Data Analyst | B36: Data Analyst | D36: via LinkedIn | E36: Full-time | F36: FALSE | G36: New York, United States | H36: 44929.686 | I36: TRUE | J36: FALSE | K36: United States | L36: year | M36: 97500 | O36: Robert Half | P36: ['sql', 't-sql', 'sql server', 'azure', 'ssrs', 'ssis']
A37: Data Engineer | B37: Data Engineer | C37: Washington, DC | D37: via PHL17 Jobs | E37: Full-time | F37: FALSE | G37: Georgia | H37: 44941.583 | I37: FALSE | J37: FALSE | K37: United States | L37: year | M37: 145000 | O37: Peraton | P37: ['python', 'sql', 'neo4j', 'mysql', 'aws', 'spark', 'express', 'splunk', 'git', 'jira', 'confluence']
A38: Data Engineer | B38: Data Engineer - A4370 | C38: Pleasanton, CA | D38: via Ai-Jobs.net | E38: Full-time | F38: FALSE | G38: California, United States | H38: 44937.839 | I38: FALSE | J38: TRUE | K38: United States | L38: year | M38: 147500 | O38: Nisum | P38: ['sql', 'spark']
A39: Senior Data Engineer | B39: Senior Data Engineer | C39: Woonsocket, RI | D39: via Indeed | E39: Full-time | F39: FALSE | G39: Illinois, United States | H39: 44933.921 | I39: FALSE | J39: TRUE | K39: United States | L39: year | M39: 135000 | O39: CVS Health | P39: ['sql', 'python', 'bash', 'oracle', 'snowflake', 'azure', 'gcp', 'hadoop']
A40: Senior Data Analyst | B40: Senior Data Analyst, Business Optimization | C40: Smyrna, GA | D40: via ZipRecruiter | E40: Full-time | F40: FALSE | G40: Georgia | H40: 44953.436 | I40: FALSE | J40: TRUE | K40: United States | L40: year | M40: 96500 | O40: Cox Communications | P40: ['swift', 'sql', 'excel', 'powerpoint', 'microstrategy', 'tableau']
...

Sheet Jan - Move or Copy
A1: job_title_short | B1: job_title | C1: job_location | D1: job_via | E1: job_schedule_type | F1: job_work_from_home | G1: search_location | H1: job_posted_date | I1: job_no_degree_mention | J1: job_health_insurance | K1: job_country | L1: salary_rate | M1: salary_year_avg | N1: salary_hour_avg | O1: company_name | P1: job_skills
A2: Data Scientist | B2: Data Scientist - TikTok Ads | C2: Mountain View, CA | D2: via LinkedIn | E2: Full-time | F2: FALSE | G2: California, United States | H2: 44928.626 | I2: FALSE | J2: TRUE | K2: United States | L2: year | M2: 224500 | O2: TikTok | P2: ['r', 'python', 'matlab', 'sql']
A3: Data Scientist | B3: Data Scientist - Technical Platform | C3: Mountain View, CA | D3: via LinkedIn | E3: Full-time | F3: FALSE | G3: California, United States | H3: 44938.17 | I3: FALSE | J3: TRUE | K3: United States | L3: year | M3: 157500 | O3: TikTok | P3: ['sql', 'python']
A4: Data Scientist | B4: Data Scientist - Computer Vision | C4: Paris, France | D4: via Ai-Jobs.net | E4: Full-time | F4: FALSE | G4: France | H4: 44956.343 | I4: FALSE | J4: FALSE | K4: France | L4: year | M4: 88128 | O4: digiRocks | P4: ['python', 'c++', 'pytorch', 'tensorflow', 'keras']
A5: Data Scientist | B5: Senior Actuarial Consultant and Data Scientist - Remote | C5: Las Vegas, NV | D5: via Las Vegas, NV - Geebo | E5: Full-time | F5: FALSE | G5: California, United States | H5: 44953.004 | I5: FALSE | J5: TRUE | K5: United States | L5: hour | N5: 24 | O5: UnitedHealth Group | P5: ['r', 'python', 'vba', 'sas', 'sas', 'sql', 'databricks', 'excel']
A6: Data Scientist | B6: Data Scientist Digital Effectiveness Operations & Technology Analytics | C6: Sun City, AZ | D6: via ZipRecruiter | E6: Full-time | F6: FALSE | G6: California, United States | H6: 44955.42 | I6: FALSE | J6: TRUE | K6: United States | L6: year | M6: 105800 | O6: Cox Communications | P6: ['sql', 'python', 'aws', 'pandas', 'numpy', 'scikit-learn', 'pyspark', 'tableau']
A7: Data Scientist | B7: Data Scientist - Marketing Analytics | C7: Irving, TX | D7: via LinkedIn | E7: Full-time | F7: FALSE | G7: Texas, United States | H7: 44950.668 | I7: FALSE | J7: TRUE | K7: United States | L7: year | M7: 115000 | O7: Cottonwood Financial | P7: ['sql', 'sas', 'sas', 'python', 'r']
A8: Senior Data Analyst | B8: Senior Data Analyst Business Optimization Intelligence | C8: Bailey's Crossroads, VA | D8: via ZipRecruiter | E8: Full-time | F8: FALSE | G8: New York, United States | H8: 44930.417 | I8: FALSE | J8: TRUE | K8: United States | L8: year | M8: 96500 | O8: Cox Communications | P8: ['sql', 'snowflake', 'aws', 'microstrategy', 'tableau', 'excel']
A9: Data Engineer | B9: IT & Strategy Talent Programme - AI/ML and Data Engineer | C9: Hamburg, Germany | D9: via Ai-Jobs.net | E9: Full-time | F9: FALSE | G9: Germany | H9: 44938.864 | I9: FALSE | J9: FALSE | K9: Germany | L9: year | M9: 98301.5 | O9: Vattenfall | P9: ['azure']
A10: Senior Data Scientist | B10: Senior Data Scientist | C10: El Mirage, AZ | D10: via ZipRecruiter | E10: Full-time | F10: FALSE | G10: California, United States | H10: 44955.42 | I10: FALSE | J10: TRUE | K10: United States | L10: year | M10: 116700 | O10: Cox Communications | P10: ['sql', 'r', 'python', 'scala', 'java', 'c++', 'sas', 'sas', 'aws', 'spark', 'ggplot2', 'pandas', 'numpy', 'scikit-learn', 'tableau']
A11: Data Engineer | B11: Data Engineer | C11: Chicago, IL | D11: via Indeed | E11: Full-time | F11: FALSE | G11: California, United States | H11: 44939.798 | I11: FALSE | J11: TRUE | K11: United States | L11: year | M11: 102500 | O11: Alliant Credit Union | P11: ['sql', 'azure', 'tableau']
A12: Senior Data Scientist | B12: Senior Data Scientist | C12: Austin, TX | D12: via Indeed | E12: Full-time | F12: FALSE | G12: Texas, United States | H12: 44930.92 | I12: FALSE | J12: TRUE | K12: United States | L12: year | M12: 145000 | O12: CyberCoders | P12: ['python', 'azure', 'pytorch', 'tensorflow', 'opencv', 'datarobot']
A13: Data Engineer | B13: Systems & Data Engineer | C13: Boston, MA | D13: via LinkedIn | E13: Full-time | F13: FALSE | G13: Illinois, United States | H13: 44952.675 | I13: FALSE | J13: TRUE | K13: United States | L13: year | M13: 75000 | O13: New England Board of Higher Education | P13: ['sql', 'python', 'r', 'java', 'scala', 'aws', 'azure', 'tableau']
A14: Data Engineer | B14: Data Engineer | C14: Anywhere | D14: via LinkedIn | E14: Full-time | F14: TRUE | G14: Florida, United States | H14: 44944.634 | I14: TRUE | J14: FALSE | K14: United States | L14: year | M14: 105000 | O14: HirePlace | P14: ['no-sql', 'sql', 'python', 'scala', 'java', 'bash', 'powershell', 'azure', 'databricks', 'spark']
A15: Data Engineer | B15: Jr. Data Engineer | C15: Madison, WI | D15: via Ladders | E15: Full-time | F15: FALSE | G15: New York, United States | H15: 44935.087 | I15: FALSE | J15: FALSE | K15: United States | L15: year | M15: 90000 | O15: Baker Tilly | P15: ['sql', 'python', 'r', 'sql server', 'azure', 'databricks']
A16: Data Scientist | B16: Data Science Manager, Specialist Master - SFL Scientific | C16: San Jose, CA | D16: via Ladders | E16: Full-time | F16: FALSE | G16: California, United States | H16: 44946.515 | I16: FALSE | J16: FALSE | K16: United States | L16: year | M16: 200000 | O16: Deloitte | P16: ['python', 'aws', 'azure', 'gcp', 'keras', 'tensorflow', 'pytorch', 'pandas', 'scikit-learn', 'jupyter']
A17: Data Scientist | B17: Data Scientist I | C17: Boston, MA | D17: via ZipRecruiter | E17: Full-time | F17: FALSE | G17: New York, United States | H17: 44931.669 | I17: FALSE | J17: FALSE | K17: United States | L17: year | M17: 57500 | O17: Tresume and Asta CRS | P17: ['r', 'sql', 'python', 'scala', 'java', 'c++']
A18: Data Analyst | B18: Lead-Data Analyst | C18: St James, MO | D18: via My ArkLaMiss Jobs | E18: Full-time | F18: FALSE | G18: Illinois, United States | H18: 44928.751 | I18: FALSE | J18: TRUE | K18: United States | L18: year | M18: 144481.5 | O18: EDWARD JONES
A19: Data Scientist | B19: Data Science Instructor | C19: San Antonio, TX | D19: via LinkedIn | E19: Full-time | F19: FALSE | G19: Sudan | H19: 44936.752 | I19: FALSE | J19: TRUE | K19: Sudan | L19: year | M19: 77500 | O19: Codeup | P19: ['python', 'sql', 'matplotlib', 'seaborn', 'spark', 'hadoop', 'jupyter', 'tableau']
A20: Data Engineer | B20: Big Data Engineer | C20: Chicago, IL | D20: via LinkedIn | E20: Full-time | F20: FALSE | G20: Sudan | H20: 44952.328 | I20: FALSE | J20: FALSE | K20: Sudan | L20: year | M20: 105000 | O20: Robert Half | P20: ['python', 'sql', 'go', 'aws', 'databricks', 'spark', 'pyspark', 'airflow', 'alteryx', 'tableau']
A21: Data Analyst | B21: Institutional Credit Management - Lending Data Analyst - Vice... | C21: Pinellas Park, FL | D21: via ComputerWork | E21: Full-time | F21: FALSE | G21: Florida, United States | H21: 44951.669 | I21: FALSE | J21: FALSE | K21: United States | L21: year | M21: 132315 | O21: Citi | P21: ['cognos', 'tableau']
A22: Senior Data Scientist | B22: AI/ML - Senior Data Science Manager, AI/ML Data | C22: Cupertino, CA | D22: via My Champlain Valley Jobs | E22: Full-time | F22: FALSE | G22: California, United States | H22: 44938.754 | I22: FALSE | J22: TRUE | K22: United States | L22: year | M22: 173000 | O22: Apple
A23: Data Analyst | B23: Experian Data Analyst Remote / Telecommute Jobs | C23: Anywhere | D23: via Clearance Jobs | E23: Full-time | F23: TRUE | G23: New York, United States | H23: 44929.894 | I23: FALSE | J23: FALSE | K23: United States | L23: year | M23: 112500 | O23: Seneca Resources, LLC | P23: ['aws', 'linux']
A24: Data Scientist | B24: Electronics Data Scientist Intern | C24: Anywhere | D24: via Indeed | E24: Full-time | F24: TRUE | G24: California, United States | H24: 44953.379 | I24: FALSE | J24: FALSE | K24: United States | L24: hour | N24: 21.75 | O24: MilliporeSigma | P24: ['excel', 'outlook']
A25: Data Scientist | B25: Data Scientist (Genomics/Genetics, Python, AWS) - no c2c | C25: Anywhere | D25: via LinkedIn | E25: Contractor | F25: TRUE | G25: Texas, United States | H25: 44935.753 | I25: FALSE | J25: FALSE | K25: United States | L25: hour | N25: 66.5 | O25: neteffects | P25: ['python', 'r', 'sql', 'java', 'aws', 'gcp', 'airflow', 'docker', 'git', 'kubernetes']
A26: Senior Data Analyst | B26: Senior Data Analyst | C26: Ontario, CA | D26: via Indeed | E26: Full-time | F26: FALSE | G26: California, United States | H26: 44937.418 | I26: FALSE | J26: TRUE | K26: United States | L26: hour | N26: 34.875 | O26: Prime Healthcare Management Inc | P26: ['sql', 'excel']
A27: Data Analyst | B27: Data Analyst (Remote) | C27: Anywhere | D27: via Indeed | E27: Full-time | F27: TRUE | G27: Georgia | H27: 44940.405 | I27: FALSE | J27: FALSE | K27: United States | L27: year | M27: 52500 | O27: Acosta, Inc. | P27: ['windows', 'excel', 'word', 'powerpoint', 'power bi']
A28: Data Engineer | B28: Sr. Data Engineer | C28: Austin, TX | D28: via Indeed | E28: Full-time | F28: FALSE | G28: Georgia | H28: 44947.598 | I28: TRUE | J28: FALSE | K28: United States | L28: year | M28: 164500 | O28: Charles Schwab | P28: ['sql', 'python', 'java', 'gcp', 'bigquery', 'aws', 'vmware', 'pandas', 'spark', 'airflow', 'kafka', 'splunk', 'tableau', 'jira', 'confluence']
A29: Data Engineer | B29: Scientific Data Engineer (Remote Friendly) | C29: Anywhere | D29: via LinkedIn | E29: Full-time | F29: TRUE | G29: Texas, United States | H29: 44951.975 | I29: FALSE | J29: FALSE | K29: United States | L29: year | M29: 149874 | O29: Berkeley Lab | P29: ['python', 'java', 'javascript', 'bash', 'nosql', 'mysql', 'oracle', 'aws', 'linux']
A30: Data Analyst | B30: Lead Business Data Analyst - Global Delivery Services | C30: Santa Fe, NM | D30: via DirectlyApply | E30: Full-time | F30: FALSE | G30: Sudan | H30: 44932.163 | I30: TRUE | J30: FALSE | K30: Sudan | L30: year | M30: 115775 | O30: UKG (Ultimate Kronos Group) | P30: ['power bi', 'excel', 'tableau']
A31: Senior Data Analyst | B31: Senior Data Analyst - Cox Communities | C31: Oakton, VA | D31: via ZipRecruiter | E31: Full-time | F31: FALSE | G31: New York, United States | H31: 44930.417 | I31: FALSE | J31: TRUE | K31: United States | L31: year | M31: 96500 | O31: Cox Communications | P31: ['sql', 'alteryx', 'tableau']
A32: Senior Data Scientist | B32: Senior Data Scientist , Health Equity – Chicago, Boston, OR Remote | C32: Anywhere | D32: via Indeed | E32: Full-time | F32: TRUE | G32: Illinois, United States | H32: 44942.905 | I32: FALSE | J32: TRUE | K32: United States | L32: year | M32: 135000 | O32: CVS Health | P32: ['python', 'sql', 'gcp', 'azure', 'aws', 'hadoop']
A33: Data Scientist | B33: Manufacturing Data Scientist | C33: Englewood, CO | D33: via Indeed | E33: Full-time | F33: FALSE | G33: Sudan | H33: 44939.891 | I33: FALSE | J33: FALSE | K33: Sudan | L33: year | M33: 110000 | O33: Scytec Consulting Inc. | P33: ['sql', 'nosql', 'mongodb', 'mongodb', 'c#', 'sql server', 'azure', 'aws', 'git']
A34: Data Engineer | B34: Data Engineer | C34: New York, NY | D34: via LinkedIn | E34: Full-time | F34: FALSE | G34: Texas, United States | H34: 44950.632 | I34: FALSE | J34: FALSE | K34: United States | L34: year | M34: 155000 | O34: Revel IT | P34: ['sql', 'nosql', 'python', 'ruby', 'ruby', 'mysql', 'redshift', 'aws', 'tableau']
A35: Data Scientist | B35: Mathematics Statistician or Statistician (Data Scientist) 12 Month... | C35: Buffalo, NY | D35: via Buffalo, NY - Geebo | E35: Full-time | F35: FALSE | G35: Illinois, United States | H35: 44942.003 | I35: FALSE | J35: TRUE | K35: United States | L35: hour | N35: 24 | O35: Internal Revenue Service | P35: ['c', 'r', 'python', 'sql', 'java', 'oracle']
A36: Data Analyst | B36: Data Analyst | D36: via LinkedIn | E36: Full-time | F36: FALSE | G36: New York, United States | H36: 44929.686 | I36: TRUE | J36: FALSE | K36: United States | L36: year | M36: 97500 | O36: Robert Half | P36: ['sql', 't-sql', 'sql server', 'azure', 'ssrs', 'ssis']
A37: Data Engineer | B37: Data Engineer | C37: Washington, DC | D37: via PHL17 Jobs | E37: Full-time | F37: FALSE | G37: Georgia | H37: 44941.583 | I37: FALSE | J37: FALSE | K37: United States | L37: year | M37: 145000 | O37: Peraton | P37: ['python', 'sql', 'neo4j', 'mysql', 'aws', 'spark', 'express', 'splunk', 'git', 'jira', 'confluence']
A38: Data Engineer | B38: Data Engineer - A4370 | C38: Pleasanton, CA | D38: via Ai-Jobs.net | E38: Full-time | F38: FALSE | G38: California, United States | H38: 44937.839 | I38: FALSE | J38: TRUE | K38: United States | L38: year | M38: 147500 | O38: Nisum | P38: ['sql', 'spark']
A39: Senior Data Engineer | B39: Senior Data Engineer | C39: Woonsocket, RI | D39: via Indeed | E39: Full-time | F39: FALSE | G39: Illinois, United States | H39: 44933.921 | I39: FALSE | J39: TRUE | K39: United States | L39: year | M39: 135000 | O39: CVS Health | P39: ['sql', 'python', 'bash', 'oracle', 'snowflake', 'azure', 'gcp', 'hadoop']
A40: Senior Data Analyst | B40: Senior Data Analyst, Business Optimization | C40: Smyrna, GA | D40: via ZipRecruiter | E40: Full-time | F40: FALSE | G40: Georgia | H40: 44953.436 | I40: FALSE | J40: TRUE | K40: United States | L40: year | M40: 96500 | O40: Cox Communications | P40: ['swift', 'sql', 'excel', 'powerpoint', 'microstrategy', 'tableau']
...

Sheet Skills Analysis
A1: Skills Demand Analysis — Data Job Postings, January 2023
A2: Source: 'Jan - Copy & Paste' (columns A, M, P). All figures are formula-driven.
A4: Dataset summary
A5: Total job postings | B5: =COUNTA('Jan - Copy & Paste'!$A$2:$A$3103) -> 3102
A6: Postings with skills listed | B6: =COUNTIF('Jan - Copy & Paste'!$P$2:$P$3103,"*'*") -> 2821
A7: Postings with annual salary | B7: =COUNTIF('Jan - Copy & Paste'!$M$2:$M$3103,">0") -> 2287
A8: Overall avg annual salary | B8: =AVERAGEIF('Jan - Copy & Paste'!$M$2:$M$3103,">0") -> 123064.16
A9: Distinct skills in dataset | B9: 179
A11: Rank | B11: Skill | C11: Postings | D11: % of skilled postings | E11: Avg salary ($/yr) | F11: vs overall avg | G11: Salary sample (n)
A12: =RANK(C12,$C$12:$C$36) -> 1 | B12: sql | C12: =COUNTIF('Jan - Copy & Paste'!$P$2:$P$3103,"*'"&$B12&"'*") -> 1793 | D12: =C12/$B$6 -> 0.63559022 | E12: =AVERAGEIFS('Jan - Copy & Paste'!$M$2:$M$3103,'Jan - Copy & Paste'!$P$2:$P$3103,"*'"&$B12&"'*",'Jan - Copy & Paste'!$M$2:$M$3103,">0") -> 125281.34 | F12: =E12/$B$8-1 -> 0.018016437 | G12: =COUNTIFS('Jan - Copy & Paste'!$P$2:$P$3103,"*'"&$B12&"'*",'Jan - Copy & Paste'!$M$2:$M$3103,">0") -> 1344
A13: =RANK(C13,$C$12:$C$36) -> 2 | B13: python | C13: =COUNTIF('Jan - Copy & Paste'!$P$2:$P$3103,"*'"&$B13&"'*") -> 1657 | D13: =C13/$B$6 -> 0.58738036 | E13: =AVERAGEIFS('Jan - Copy & Paste'!$M$2:$M$3103,'Jan - Copy & Paste'!$P$2:$P$3103,"*'"&$B13&"'*",'Jan - Copy & Paste'!$M$2:$M$3103,">0") -> 132378.18 | F13: =E13/$B$8-1 -> 0.075684247 | G13: =COUNTIFS('Jan - Copy & Paste'!$P$2:$P$3103,"*'"&$B13&"'*",'Jan - Copy & Paste'!$M$2:$M$3103,">0") -> 1338
A14: =RANK(C14,$C$12:$C$36) -> 3 | B14: r | C14: =COUNTIF('Jan - Copy & Paste'!$P$2:$P$3103,"*'"&$B14&"'*") -> 710 | D14: =C14/$B$6 -> 0.2516838 | E14: =AVERAGEIFS('Jan - Copy & Paste'!$M$2:$M$3103,'Jan - Copy & Paste'!$P$2:$P$3103,"*'"&$B14&"'*",'Jan - Copy & Paste'!$M$2:$M$3103,">0") -> 128126.73 | F14: =E14/$B$8-1 -> 0.041137669 | G14: =COUNTIFS('Jan - Copy & Paste'!$P$2:$P$3103,"*'"&$B14&"'*",'Jan - Copy & Paste'!$M$2:$M$3103,">0") -> 559
A15: =RANK(C15,$C$12:$C$36) -> 4 | B15: tableau | C15: =COUNTIF('Jan - Copy & Paste'!$P$2:$P$3103,"*'"&$B15&"'*") -> 650 | D15: =C15/$B$6 -> 0.23041475 | E15: =AVERAGEIFS('Jan - Copy & Paste'!$M$2:$M$3103,'Jan - Copy & Paste'!$P$2:$P$3103,"*'"&$B15&"'*",'Jan - Copy & Paste'!$M$2:$M$3103,">0") -> 114357.86 | F15: =E15/$B$8-1 -> -0.070746 | G15: =COUNTIFS('Jan - Copy & Paste'!$P$2:$P$3103,"*'"&$B15&"'*",'Jan - Copy & Paste'!$M$2:$M$3103,">0") -> 497
A16: =RANK(C16,$C$12:$C$36) -> 5 | B16: excel | C16: =COUNTIF('Jan - Copy & Paste'!$P$2:$P$3103,"*'"&$B16&"'*") -> 646 | D16: =C16/$B$6 -> 0.22899681 | E16: =AVERAGEIFS('Jan - Copy & Paste'!$M$2:$M$3103,'Jan - Copy & Paste'!$P$2:$P$3103,"*'"&$B16&"'*",'Jan - Copy & Paste'!$M$2:$M$3103,">0") -> 99670.414 | F16: =E16/$B$8-1 -> -0.19009391 | G16: =COUNTIFS('Jan - Copy & Paste'!$P$2:$P$3103,"*'"&$B16&"'*",'Jan - Copy & Paste'!$M$2:$M$3103,">0") -> 419
A17: =RANK(C17,$C$12:$C$36) -> 6 | B17: aws | C17: =COUNTIF('Jan - Copy & Paste'!$P$2:$P$3103,"*'"&$B17&"'*") -> 594 | D17: =C17/$B$6 -> 0.21056363 | E17: =AVERAGEIFS('Jan - Copy & Paste'!$M$2:$M$3103,'Jan - Copy & Paste'!$P$2:$P$3103,"*'"&$B17&"'*",'Jan - Copy & Paste'!$M$2:$M$3103,">0") -> 137935.96 | F17: =E17/$B$8-1 -> 0.12084589 | G17: =COUNTIFS('Jan - Copy & Paste'!$P$2:$P$3103,"*'"&$B17&"'*",'Jan - Copy & Paste'!$M$2:$M$3103,">0") -> 480
A18: =RANK(C18,$C$12:$C$36) -> 7 | B18: spark | C18: =COUNTIF('Jan - Copy & Paste'!$P$2:$P$3103,"*'"&$B18&"'*") -> 498 | D18: =C18/$B$6 -> 0.17653314 | E18: =AVERAGEIFS('Jan - Copy & Paste'!$M$2:$M$3103,'Jan - Copy & Paste'!$P$2:$P$3103,"*'"&$B18&"'*",'Jan - Copy & Paste'!$M$2:$M$3103,">0") -> 141550.54 | F18: =E18/$B$8-1 -> 0.15021738 | G18: =COUNTIFS('Jan - Copy & Paste'!$P$2:$P$3103,"*'"&$B18&"'*",'Jan - Copy & Paste'!$M$2:$M$3103,">0") -> 426
A19: =RANK(C19,$C$12:$C$36) -> 8 | B19: azure | C19: =COUNTIF('Jan - Copy & Paste'!$P$2:$P$3103,"*'"&$B19&"'*") -> 414 | D19: =C19/$B$6 -> 0.14675647 | E19: =AVERAGEIFS('Jan - Copy & Paste'!$M$2:$M$3103,'Jan - Copy & Paste'!$P$2:$P$3103,"*'"&$B19&"'*",'Jan - Copy & Paste'!$M$2:$M$3103,">0") -> 130034.88 | F19: =E19/$B$8-1 -> 0.056642932 | G19: =COUNTIFS('Jan - Copy & Paste'!$P$2:$P$3103,"*'"&$B19&"'*",'Jan - Copy & Paste'!$M$2:$M$3103,">0") -> 343
A20: =RANK(C20,$C$12:$C$36) -> 9 | B20: java | C20: =COUNTIF('Jan - Copy & Paste'!$P$2:$P$3103,"*'"&$B20&"'*") -> 328 | D20: =C20/$B$6 -> 0.11627083 | E20: =AVERAGEIFS('Jan - Copy & Paste'!$M$2:$M$3103,'Jan - Copy & Paste'!$P$2:$P$3103,"*'"&$B20&"'*",'Jan - Copy & Paste'!$M$2:$M$3103,">0") -> 131235.19 | F20: =E20/$B$8-1 -> 0.066396516 | G20: =COUNTIFS('Jan - Copy & Paste'!$P$2:$P$3103,"*'"&$B20&"'*",'Jan - Copy & Paste'!$M$2:$M$3103,">0") -> 283
A21: =RANK(C21,$C$12:$C$36) -> 10 | B21: power bi | C21: =COUNTIF('Jan - Copy & Paste'!$P$2:$P$3103,"*'"&$B21&"'*") -> 324 | D21: =C21/$B$6 -> 0.11485289 | E21: =AVERAGEIFS('Jan - Copy & Paste'!$M$2:$M$3103,'Jan - Copy & Paste'!$P$2:$P$3103,"*'"&$B21&"'*",'Jan - Copy & Paste'!$M$2:$M$3103,">0") -> 104707.91 | F21: =E21/$B$8-1 -> -0.14916004 | G21: =COUNTIFS('Jan - Copy & Paste'!$P$2:$P$3103,"*'"&$B21&"'*",'Jan - Copy & Paste'!$M$2:$M$3103,">0") -> 252
A22: =RANK(C22,$C$12:$C$36) -> 11 | B22: hadoop | C22: =COUNTIF('Jan - Copy & Paste'!$P$2:$P$3103,"*'"&$B22&"'*") -> 291 | D22: =C22/$B$6 -> 0.10315491 | E22: =AVERAGEIFS('Jan - Copy & Paste'!$M$2:$M$3103,'Jan - Copy & Paste'!$P$2:$P$3103,"*'"&$B22&"'*",'Jan - Copy & Paste'!$M$2:$M$3103,">0") -> 141100.97 | F22: =E22/$B$8-1 -> 0.14656426 | G22: =COUNTIFS('Jan - Copy & Paste'!$P$2:$P$3103,"*'"&$B22&"'*",'Jan - Copy & Paste'!$M$2:$M$3103,">0") -> 242
A23: =RANK(C23,$C$12:$C$36) -> 12 | B23: snowflake | C23: =COUNTIF('Jan - Copy & Paste'!$P$2:$P$3103,"*'"&$B23&"'*") -> 281 | D23: =C23/$B$6 -> 0.099610067 | E23: =AVERAGEIFS('Jan - Copy & Paste'!$M$2:$M$3103,'Jan - Copy & Paste'!$P$2:$P$3103,"*'"&$B23&"'*",'Jan - Copy & Paste'!$M$2:$M$3103,">0") -> 137522.69 | F23: =E23/$B$8-1 -> 0.11748768 | G23: =COUNTIFS('Jan - Copy & Paste'!$P$2:$P$3103,"*'"&$B23&"'*",'Jan - Copy & Paste'!$M$2:$M$3103,">0") -> 233
... A36: =RANK(C36,$C$12:$C$36) -> 25 | B36: databricks | C36: =COUNTIF('Jan - Copy & Paste'!$P$2:$P$3103,"*'"&$B36&"'*") -> 166 | D36: =C36/$B$6 -> 0.058844381 | E36: =AVERAGEIFS('Jan - Copy & Paste'!$M$2:$M$3103,'Jan - Copy & Paste'!$P$2:$P$3103,"*'"&$B36&"'*",'Jan - Copy & Paste'!$M$2:$M$3103,">0") -> 133015.12 | F36: =E36/$B$8-1 -> 0.080859921 | G36: =COUNTIFS('Jan - Copy & Paste'!$P$2:$P$3103,"*'"&$B36&"'*",'Jan - Copy & Paste'!$M$2:$M$3103,">0") -> 124
A39: Top skills by role — % of that role's postings mentioning the skill
B41: Skill | C41: Data Analyst | D41: Data Scientist | E41: Data Engineer | F41: Senior Data Analyst | G41: Senior Data Scientist | H41: Senior Data Engineer | I41: Machine Learning Engineer
B42: Postings in role | C42: =COUNTIF('Jan - Copy & Paste'!$A$2:$A$3103,C$41) -> 982 | D42: =COUNTIF('Jan - Copy & Paste'!$A$2:$A$3103,D$41) -> 869 | E42: =COUNTIF('Jan - Copy & Paste'!$A$2:$A$3103,E$41) -> 522 | F42: =COUNTIF('Jan - Copy & Paste'!$A$2:$A$3103,F$41) -> 191 | G42: =COUNTIF('Jan - Copy & Paste'!$A$2:$A$3103,G$41) -> 236 | H42: =COUNTIF('Jan - Copy & Paste'!$A$2:$A$3103,H$41) -> 145 | I42: =COUNTIF('Jan - Copy & Paste'!$A$2:$A$3103,I$41) -> 74
B43: sql | C43: =COUNTIFS('Jan - Copy & Paste'!$A$2:$A$3103,C$41,'Jan - Copy & Paste'!$P$2:$P$3103,"*'"&$B43&"'*")/C$42 -> 0.53869654 | D43: =COUNTIFS('Jan - Copy & Paste'!$A$2:$A$3103,D$41,'Jan - Copy & Paste'!$P$2:$P$3103,"*'"&$B43&"'*")/D$42 -> 0.54890679 | E43: =COUNTIFS('Jan - Copy & Paste'!$A$2:$A$3103,E$41,'Jan - Copy & Paste'!$P$2:$P$3103,"*'"&$B43&"'*")/E$42 -> 0.66858238 | F43: =COUNTIFS('Jan - Copy & Paste'!$A$2:$A$3103,F$41,'Jan - Copy & Paste'!$P$2:$P$3103,"*'"&$B43&"'*")/F$42 -> 0.7382199 | G43: =COUNTIFS('Jan - Copy & Paste'!$A$2:$A$3103,G$41,'Jan - Copy & Paste'!$P$2:$P$3103,"*'"&$B43&"'*")/G$42 -> 0.61440678 | H43: =COUNTIFS('Jan - Copy & Paste'!$A$2:$A$3103,H$41,'Jan - Copy & Paste'!$P$2:$P$3103,"*'"&$B43&"'*")/H$42 -> 0.69655172 | I43: =COUNTIFS('Jan - Copy & Paste'!$A$2:$A$3103,I$41,'Jan - Copy & Paste'!$P$2:$P$3103,"*'"&$B43&"'*")/I$42 -> 0.22972973
B44: python | C44: =COUNTIFS('Jan - Copy & Paste'!$A$2:$A$3103,C$41,'Jan - Copy & Paste'!$P$2:$P$3103,"*'"&$B44&"'*")/C$42 -> 0.27494908 | D44: =COUNTIFS('Jan - Copy & Paste'!$A$2:$A$3103,D$41,'Jan - Copy & Paste'!$P$2:$P$3103,"*'"&$B44&"'*")/D$42 -> 0.72036824 | E44: =COUNTIFS('Jan - Copy & Paste'!$A$2:$A$3103,E$41,'Jan - Copy & Paste'!$P$2:$P$3103,"*'"&$B44&"'*")/E$42 -> 0.63793103 | F44: =COUNTIFS('Jan - Copy & Paste'!$A$2:$A$3103,F$41,'Jan - Copy & Paste'!$P$2:$P$3103,"*'"&$B44&"'*")/F$42 -> 0.39790576 | G44: =COUNTIFS('Jan - Copy & Paste'!$A$2:$A$3103,G$41,'Jan - Copy & Paste'!$P$2:$P$3103,"*'"&$B44&"'*")/G$42 -> 0.73728814 | H44: =COUNTIFS('Jan - Copy & Paste'!$A$2:$A$3103,H$41,'Jan - Copy & Paste'!$P$2:$P$3103,"*'"&$B44&"'*")/H$42 -> 0.73793103 | I44: =COUNTIFS('Jan - Copy & Paste'!$A$2:$A$3103,I$41,'Jan - Copy & Paste'!$P$2:$P$3103,"*'"&$B44&"'*")/I$42 -> 0.62162162
B45: r | C45: =COUNTIFS('Jan - Copy & Paste'!$A$2:$A$3103,C$41,'Jan - Copy & Paste'!$P$2:$P$3103,"*'"&$B45&"'*")/C$42 -> 0.1598778 | D45: =COUNTIFS('Jan - Copy & Paste'!$A$2:$A$3103,D$41,'Jan - Copy & Paste'!$P$2:$P$3103,"*'"&$B45&"'*")/D$42 -> 0.40391254 | E45: =COUNTIFS('Jan - Copy & Paste'!$A$2:$A$3103,E$41,'Jan - Copy & Paste'!$P$2:$P$3103,"*'"&$B45&"'*")/E$42 -> 0.063218391 | F45: =COUNTIFS('Jan - Copy & Paste'!$A$2:$A$3103,F$41,'Jan - Copy & Paste'!$P$2:$P$3103,"*'"&$B45&"'*")/F$42 -> 0.27225131 | G45: =COUNTIFS('Jan - Copy & Paste'!$A$2:$A$3103,G$41,'Jan - Copy & Paste'!$P$2:$P$3103,"*'"&$B45&"'*")/G$42 -> 0.41101695 | H45: =COUNTIFS('Jan - Copy & Paste'!$A$2:$A$3103,H$41,'Jan - Copy & Paste'!$P$2:$P$3103,"*'"&$B45&"'*")/H$42 -> 0.027586207 | I45: =COUNTIFS('Jan - Copy & Paste'!$A$2:$A$3103,I$41,'Jan - Copy & Paste'!$P$2:$P$3103,"*'"&$B45&"'*")/I$42 -> 0.12162162
B46: excel | C46: =COUNTIFS('Jan - Copy & Paste'!$A$2:$A$3103,C$41,'Jan - Copy & Paste'!$P$2:$P$3103,"*'"&$B46&"'*")/C$42 -> 0.41446029 | D46: =COUNTIFS('Jan - Copy & Paste'!$A$2:$A$3103,D$41,'Jan - Copy & Paste'!$P$2:$P$3103,"*'"&$B46&"'*")/D$42 -> 0.10701956 | E46: =COUNTIFS('Jan - Copy & Paste'!$A$2:$A$3103,E$41,'Jan - Copy & Paste'!$P$2:$P$3103,"*'"&$B46&"'*")/E$42 -> 0.042145594 | F46: =COUNTIFS('Jan - Copy & Paste'!$A$2:$A$3103,F$41,'Jan - Copy & Paste'!$P$2:$P$3103,"*'"&$B46&"'*")/F$42 -> 0.39267016 | G46: =COUNTIFS('Jan - Copy & Paste'!$A$2:$A$3103,G$41,'Jan - Copy & Paste'!$P$2:$P$3103,"*'"&$B46&"'*")/G$42 -> 0.093220339 | H46: =COUNTIFS('Jan - Copy & Paste'!$A$2:$A$3103,H$41,'Jan - Copy & Paste'!$P$2:$P$3103,"*'"&$B46&"'*")/H$42 -> 0.020689655 | I46: =COUNTIFS('Jan - Copy & Paste'!$A$2:$A$3103,I$41,'Jan - Copy & Paste'!$P$2:$P$3103,"*'"&$B46&"'*")/I$42 -> 0.013513514
B47: tableau | C47: =COUNTIFS('Jan - Copy & Paste'!$A$2:$A$3103,C$41,'Jan - Copy & Paste'!$P$2:$P$3103,"*'"&$B47&"'*")/C$42 -> 0.26782077 | D47: =COUNTIFS('Jan - Copy & Paste'!$A$2:$A$3103,D$41,'Jan - Copy & Paste'!$P$2:$P$3103,"*'"&$B47&"'*")/D$42 -> 0.18757192 | E47: =COUNTIFS('Jan - Copy & Paste'!$A$2:$A$3103,E$41,'Jan - Copy & Paste'!$P$2:$P$3103,"*'"&$B47&"'*")/E$42 -> 0.11494253 | F47: =COUNTIFS('Jan - Copy & Paste'!$A$2:$A$3103,F$41,'Jan - Copy & Paste'!$P$2:$P$3103,"*'"&$B47&"'*")/F$42 -> 0.46073298 | G47: =COUNTIFS('Jan - Copy & Paste'!$A$2:$A$3103,G$41,'Jan - Copy & Paste'!$P$2:$P$3103,"*'"&$B47&"'*")/G$42 -> 0.18220339 | H47: =COUNTIFS('Jan - Copy & Paste'!$A$2:$A$3103,H$41,'Jan - Copy & Paste'!$P$2:$P$3103,"*'"&$B47&"'*")/H$42 -> 0.068965517 | I47: =COUNTIFS('Jan - Copy & Paste'!$A$2:$A$3103,I$41,'Jan - Copy & Paste'!$P$2:$P$3103,"*'"&$B47&"'*")/I$42 -> 0.027027027
B48: power bi | C48: =COUNTIFS('Jan - Copy & Paste'!$A$2:$A$3103,C$41,'Jan - Copy & Paste'!$P$2:$P$3103,"*'"&$B48&"'*")/C$42 -> 0.14663951 | D48: =COUNTIFS('Jan - Copy & Paste'!$A$2:$A$3103,D$41,'Jan - Copy & Paste'!$P$2:$P$3103,"*'"&$B48&"'*")/D$42 -> 0.065592635 | E48: =COUNTIFS('Jan - Copy & Paste'!$A$2:$A$3103,E$41,'Jan - Copy & Paste'!$P$2:$P$3103,"*'"&$B48&"'*")/E$42 -> 0.082375479 | F48: =COUNTIFS('Jan - Copy & Paste'!$A$2:$A$3103,F$41,'Jan - Copy & Paste'!$P$2:$P$3103,"*'"&$B48&"'*")/F$42 -> 0.2565445 | G48: =COUNTIFS('Jan - Copy & Paste'!$A$2:$A$3103,G$41,'Jan - Copy & Paste'!$P$2:$P$3103,"*'"&$B48&"'*")/G$42 -> 0.050847458 | H48: =COUNTIFS('Jan - Copy & Paste'!$A$2:$A$3103,H$41,'Jan - Copy & Paste'!$P$2:$P$3103,"*'"&$B48&"'*")/H$42 -> 0.04137931 | I48: =COUNTIFS('Jan - Copy & Paste'!$A$2:$A$3103,I$41,'Jan - Copy & Paste'!$P$2:$P$3103,"*'"&$B48&"'*")/I$42 -> 0
B49: aws | C49: =COUNTIFS('Jan - Copy & Paste'!$A$2:$A$3103,C$41,'Jan - Copy & Paste'!$P$2:$P$3103,"*'"&$B49&"'*")/C$42 -> 0.040733198 | D49: =COUNTIFS('Jan - Copy & Paste'!$A$2:$A$3103,D$41,'Jan - Copy & Paste'!$P$2:$P$3103,"*'"&$B49&"'*")/D$42 -> 0.20598389 | E49: =COUNTIFS('Jan - Copy & Paste'!$A$2:$A$3103,E$41,'Jan - Copy & Paste'!$P$2:$P$3103,"*'"&$B49&"'*")/E$42 -> 0.38122605 | F49: =COUNTIFS('Jan - Copy & Paste'!$A$2:$A$3103,F$41,'Jan - Copy & Paste'!$P$2:$P$3103,"*'"&$B49&"'*")/F$42 -> 0.057591623 | G49: =COUNTIFS('Jan - Copy & Paste'!$A$2:$A$3103,G$41,'Jan - Copy & Paste'!$P$2:$P$3103,"*'"&$B49&"'*")/G$42 -> 0.23728814 | H49: =COUNTIFS('Jan - Copy & Paste'!$A$2:$A$3103,H$41,'Jan - Copy & Paste'!$P$2:$P$3103,"*'"&$B49&"'*")/H$42 -> 0.57241379 | I49: =COUNTIFS('Jan - Copy & Paste'!$A$2:$A$3103,I$41,'Jan - Copy & Paste'!$P$2:$P$3103,"*'"&$B49&"'*")/I$42 -> 0.22972973
B50: azure | C50: =COUNTIFS('Jan - Copy & Paste'!$A$2:$A$3103,C$41,'Jan - Copy & Paste'!$P$2:$P$3103,"*'"&$B50&"'*")/C$42 -> 0.040733198 | D50: =COUNTIFS('Jan - Copy & Paste'!$A$2:$A$3103,D$41,'Jan - Copy & Paste'!$P$2:$P$3103,"*'"&$B50&"'*")/D$42 -> 0.10586881 | E50: =COUNTIFS('Jan - Copy & Paste'!$A$2:$A$3103,E$41,'Jan - Copy & Paste'!$P$2:$P$3103,"*'"&$B50&"'*")/E$42 -> 0.30842912 | F50: =COUNTIFS('Jan - Copy & Paste'!$A$2:$A$3103,F$41,'Jan - Copy & Paste'!$P$2:$P$3103,"*'"&$B50&"'*")/F$42 -> 0.031413613 | G50: =COUNTIFS('Jan - Copy & Paste'!$A$2:$A$3103,G$41,'Jan - Copy & Paste'!$P$2:$P$3103,"*'"&$B50&"'*")/G$42 -> 0.14830508 | H50: =COUNTIFS('Jan - Copy & Paste'!$A$2:$A$3103,H$41,'Jan - Copy & Paste'!$P$2:$P$3103,"*'"&$B50&"'*")/H$42 -> 0.40689655 | I50: =COUNTIFS('Jan - Copy & Paste'!$A$2:$A$3103,I$41,'Jan - Copy & Paste'!$P$2:$P$3103,"*'"&$B50&"'*")/I$42 -> 0.16216216
B51: spark | C51: =COUNTIFS('Jan - Copy & Paste'!$A$2:$A$3103,C$41,'Jan - Copy & Paste'!$P$2:$P$3103,"*'"&$B51&"'*")/C$42 -> 0.025458248 | D51: =COUNTIFS('Jan - Copy & Paste'!$A$2:$A$3103,D$41,'Jan - Copy & Paste'!$P$2:$P$3103,"*'"&$B51&"'*")/D$42 -> 0.16570771 | E51: =COUNTIFS('Jan - Copy & Paste'!$A$2:$A$3103,E$41,'Jan - Copy & Paste'!$P$2:$P$3103,"*'"&$B51&"'*")/E$42 -> 0.33333333 | F51: =COUNTIFS('Jan - Copy & Paste'!$A$2:$A$3103,F$41,'Jan - Copy & Paste'!$P$2:$P$3103,"*'"&$B51&"'*")/F$42 -> 0.041884817 | G51: =COUNTIFS('Jan - Copy & Paste'!$A$2:$A$3103,G$41,'Jan - Copy & Paste'!$P$2:$P$3103,"*'"&$B51&"'*")/G$42 -> 0.22881356 | H51: =COUNTIFS('Jan - Copy & Paste'!$A$2:$A$3103,H$41,'Jan - Copy & Paste'!$P$2:$P$3103,"*'"&$B51&"'*")/H$42 -> 0.46896552 | I51: =COUNTIFS('Jan - Copy & Paste'!$A$2:$A$3103,I$41,'Jan - Copy & Paste'!$P$2:$P$3103,"*'"&$B51&"'*")/I$42 -> 0.16216216
B52: sas | C52: =COUNTIFS('Jan - Copy & Paste'!$A$2:$A$3103,C$41,'Jan - Copy & Paste'!$P$2:$P$3103,"*'"&$B52&"'*")/C$42 -> 0.080448065 | D52: =COUNTIFS('Jan - Copy & Paste'!$A$2:$A$3103,D$41,'Jan - Copy & Paste'!$P$2:$P$3103,"*'"&$B52&"'*")/D$42 -> 0.084004603 | E52: =COUNTIFS('Jan - Copy & Paste'!$A$2:$A$3103,E$41,'Jan - Copy & Paste'!$P$2:$P$3103,"*'"&$B52&"'*")/E$42 -> 0.013409962 | F52: =COUNTIFS('Jan - Copy & Paste'!$A$2:$A$3103,F$41,'Jan - Copy & Paste'!$P$2:$P$3103,"*'"&$B52&"'*")/F$42 -> 0.10994764 | G52: =COUNTIFS('Jan - Copy & Paste'!$A$2:$A$3103,G$41,'Jan - Copy & Paste'!$P$2:$P$3103,"*'"&$B52&"'*")/G$42 -> 0.084745763 | H52: =COUNTIFS('Jan - Copy & Paste'!$A$2:$A$3103,H$41,'Jan - Copy & Paste'!$P$2:$P$3103,"*'"&$B52&"'*")/H$42 -> 0.034482759 | I52: =COUNTIFS('Jan - Copy & Paste'!$A$2:$A$3103,I$41,'Jan - Copy & Paste'!$P$2:$P$3103,"*'"&$B52&"'*")/I$42 -> 0
B53: tensorflow | C53: =COUNTIFS('Jan - Copy & Paste'!$A$2:$A$3103,C$41,'Jan - Copy & Paste'!$P$2:$P$3103,"*'"&$B53&"'*")/C$42 -> 0.0030549898 | D53: =COUNTIFS('Jan - Copy & Paste'!$A$2:$A$3103,D$41,'Jan - Copy & Paste'!$P$2:$P$3103,"*'"&$B53&"'*")/D$42 -> 0.10932106 | E53: =COUNTIFS('Jan - Copy & Paste'!$A$2:$A$3103,E$41,'Jan - Copy & Paste'!$P$2:$P$3103,"*'"&$B53&"'*")/E$42 -> 0.0095785441 | F53: =COUNTIFS('Jan - Copy & Paste'!$A$2:$A$3103,F$41,'Jan - Copy & Paste'!$P$2:$P$3103,"*'"&$B53&"'*")/F$42 -> 0.010471204 | G53: =COUNTIFS('Jan - Copy & Paste'!$A$2:$A$3103,G$41,'Jan - Copy & Paste'!$P$2:$P$3103,"*'"&$B53&"'*")/G$42 -> 0.10169492 | H53: =COUNTIFS('Jan - Copy & Paste'!$A$2:$A$3103,H$41,'Jan - Copy & Paste'!$P$2:$P$3103,"*'"&$B53&"'*")/H$42 -> 0.0068965517 | I53: =COUNTIFS('Jan - Copy & Paste'!$A$2:$A$3103,I$41,'Jan - Copy & Paste'!$P$2:$P$3103,"*'"&$B53&"'*")/I$42 -> 0.33783784
B54: pytorch | C54: =COUNTIFS('Jan - Copy & Paste'!$A$2:$A$3103,C$41,'Jan - Copy & Paste'!$P$2:$P$3103,"*'"&$B54&"'*")/C$42 -> 0.0020366599 | D54: =COUNTIFS('Jan - Copy & Paste'!$A$2:$A$3103,D$41,'Jan - Copy & Paste'!$P$2:$P$3103,"*'"&$B54&"'*")/D$42 -> 0.093210587 | E54: =COUNTIFS('Jan - Copy & Paste'!$A$2:$A$3103,E$41,'Jan - Copy & Paste'!$P$2:$P$3103,"*'"&$B54&"'*")/E$42 -> 0.0076628352 | F54: =COUNTIFS('Jan - Copy & Paste'!$A$2:$A$3103,F$41,'Jan - Copy & Paste'!$P$2:$P$3103,"*'"&$B54&"'*")/F$42 -> 0.0052356021 | G54: =COUNTIFS('Jan - Copy & Paste'!$A$2:$A$3103,G$41,'Jan - Copy & Paste'!$P$2:$P$3103,"*'"&$B54&"'*")/G$42 -> 0.072033898 | H54: =COUNTIFS('Jan - Copy & Paste'!$A$2:$A$3103,H$41,'Jan - Copy & Paste'!$P$2:$P$3103,"*'"&$B54&"'*")/H$42 -> 0 | I54: =COUNTIFS('Jan - Copy & Paste'!$A$2:$A$3103,I$41,'Jan - Copy & Paste'!$P$2:$P$3103,"*'"&$B54&"'*")/I$42 -> 0.31081081
A56: Key takeaways
A57: 1. SQL and Python are the baseline: they appear in ~64% and ~59% of all postings that list skills. No other skill clears 26%.
A58: 2. Demand and pay diverge. The highest-paying skills are data-engineering tooling — Scala, Redshift, Kafka, Airflow, Spark, Hadoop (all +15% to +20% vs the $123k overall average) — despite appearing in under 18% of postings.
...
